[2025-08-10T16:40:00.121+0000] {local_task_job_runner.py:120} INFO - ::group::Pre task execution logs
[2025-08-10T16:40:00.251+0000] {taskinstance.py:2076} INFO - Dependencies all met for dep_context=non-requeueable deps ti=<TaskInstance: weather_data_pipeline.run_dbt_transformations manual__2025-08-10T16:38:41.097688+00:00 [queued]>
[2025-08-10T16:40:00.257+0000] {taskinstance.py:2076} INFO - Dependencies all met for dep_context=requeueable deps ti=<TaskInstance: weather_data_pipeline.run_dbt_transformations manual__2025-08-10T16:38:41.097688+00:00 [queued]>
[2025-08-10T16:40:00.257+0000] {taskinstance.py:2306} INFO - Starting attempt 1 of 2
[2025-08-10T16:40:00.264+0000] {taskinstance.py:2330} INFO - Executing <Task(BashOperator): run_dbt_transformations> on 2025-08-10 16:38:41.097688+00:00
[2025-08-10T16:40:00.272+0000] {standard_task_runner.py:90} INFO - Running: ['***', 'tasks', 'run', 'weather_data_pipeline', 'run_dbt_transformations', 'manual__2025-08-10T16:38:41.097688+00:00', '--job-id', '23', '--raw', '--subdir', 'DAGS_FOLDER/weather_dags.py', '--cfg-path', '/tmp/tmpztio51t1']
[2025-08-10T16:40:00.274+0000] {standard_task_runner.py:91} INFO - Job 23: Subtask run_dbt_transformations
[2025-08-10T16:40:00.274+0000] {logging_mixin.py:188} WARNING - /home/***/.local/lib/python3.12/site-packages/***/task/task_runner/standard_task_runner.py:61 DeprecationWarning: This process (pid=257) is multi-threaded, use of fork() may lead to deadlocks in the child.
[2025-08-10T16:40:00.274+0000] {standard_task_runner.py:63} INFO - Started process 259 to run task
[2025-08-10T16:40:00.317+0000] {task_command.py:426} INFO - Running <TaskInstance: weather_data_pipeline.run_dbt_transformations manual__2025-08-10T16:38:41.097688+00:00 [running]> on host 49775de909c4
[2025-08-10T16:40:00.388+0000] {taskinstance.py:2648} INFO - Exporting env vars: AIRFLOW_CTX_DAG_OWNER='Hendi Irwanto' AIRFLOW_CTX_DAG_ID='weather_data_pipeline' AIRFLOW_CTX_TASK_ID='run_dbt_transformations' AIRFLOW_CTX_EXECUTION_DATE='2025-08-10T16:38:41.097688+00:00' AIRFLOW_CTX_TRY_NUMBER='1' AIRFLOW_CTX_DAG_RUN_ID='manual__2025-08-10T16:38:41.097688+00:00'
[2025-08-10T16:40:00.389+0000] {taskinstance.py:430} INFO - ::endgroup::
[2025-08-10T16:40:00.398+0000] {subprocess.py:63} INFO - Tmp dir root location: /tmp
[2025-08-10T16:40:00.398+0000] {subprocess.py:75} INFO - Running command: ['/usr/bin/bash', '-c', 'dbt run --profiles-dir /opt/data-engineer/weather-project/dbt/weather_dbt']
[2025-08-10T16:40:00.407+0000] {subprocess.py:86} INFO - Output:
[2025-08-10T16:40:01.737+0000] {subprocess.py:93} INFO - [0m16:40:01  Running with dbt=1.10.7
[2025-08-10T16:40:01.737+0000] {subprocess.py:93} INFO - [0m16:40:01  Encountered an error:
[2025-08-10T16:40:01.738+0000] {subprocess.py:93} INFO - Runtime Error
[2025-08-10T16:40:01.738+0000] {subprocess.py:93} INFO -   No dbt_project.yml found at expected path /tmp/***tmpva9i3e0m/dbt_project.yml
[2025-08-10T16:40:01.738+0000] {subprocess.py:93} INFO -   Verify that each entry within packages.yml (and their transitive dependencies) contains a file named dbt_project.yml
[2025-08-10T16:40:01.738+0000] {subprocess.py:93} INFO - 
[2025-08-10T16:40:03.031+0000] {subprocess.py:97} INFO - Command exited with return code 2
[2025-08-10T16:40:03.032+0000] {taskinstance.py:441} INFO - ::group::Post task execution logs
[2025-08-10T16:40:03.043+0000] {taskinstance.py:2905} ERROR - Task failed with exception
Traceback (most recent call last):
  File "/home/airflow/.local/lib/python3.12/site-packages/airflow/models/taskinstance.py", line 465, in _execute_task
    result = _execute_callable(context=context, **execute_callable_kwargs)
             ^^^^^^^^^^^^^^^^^^^^^^^^^^^^^^^^^^^^^^^^^^^^^^^^^^^^^^^^^^^^^
  File "/home/airflow/.local/lib/python3.12/site-packages/airflow/models/taskinstance.py", line 432, in _execute_callable
    return execute_callable(context=context, **execute_callable_kwargs)
           ^^^^^^^^^^^^^^^^^^^^^^^^^^^^^^^^^^^^^^^^^^^^^^^^^^^^^^^^^^^^
  File "/home/airflow/.local/lib/python3.12/site-packages/airflow/models/baseoperator.py", line 401, in wrapper
    return func(self, *args, **kwargs)
           ^^^^^^^^^^^^^^^^^^^^^^^^^^^
  File "/home/airflow/.local/lib/python3.12/site-packages/airflow/operators/bash.py", line 243, in execute
    raise AirflowException(
airflow.exceptions.AirflowException: Bash command failed. The command returned a non-zero exit code 2.
[2025-08-10T16:40:03.046+0000] {taskinstance.py:1206} INFO - Marking task as UP_FOR_RETRY. dag_id=weather_data_pipeline, task_id=run_dbt_transformations, run_id=manual__2025-08-10T16:38:41.097688+00:00, execution_date=20250810T163841, start_date=20250810T164000, end_date=20250810T164003
[2025-08-10T16:40:03.054+0000] {standard_task_runner.py:110} ERROR - Failed to execute job 23 for task run_dbt_transformations (Bash command failed. The command returned a non-zero exit code 2.; 259)
[2025-08-10T16:40:03.068+0000] {local_task_job_runner.py:240} INFO - Task exited with return code 1
[2025-08-10T16:40:03.088+0000] {taskinstance.py:3503} INFO - 0 downstream tasks scheduled from follow-on schedule check
[2025-08-10T16:40:03.089+0000] {local_task_job_runner.py:222} INFO - ::endgroup::
