[2025-08-18T01:24:31.501+0000] {local_task_job_runner.py:120} INFO - ::group::Pre task execution logs
[2025-08-18T01:24:31.647+0000] {taskinstance.py:2076} INFO - Dependencies all met for dep_context=non-requeueable deps ti=<TaskInstance: weather_data_pipeline.fetch_geolocation_data scheduled__2025-08-17T00:00:00+00:00 [queued]>
[2025-08-18T01:24:31.653+0000] {taskinstance.py:2076} INFO - Dependencies all met for dep_context=requeueable deps ti=<TaskInstance: weather_data_pipeline.fetch_geolocation_data scheduled__2025-08-17T00:00:00+00:00 [queued]>
[2025-08-18T01:24:31.653+0000] {taskinstance.py:2306} INFO - Starting attempt 2 of 3
[2025-08-18T01:24:31.662+0000] {taskinstance.py:2330} INFO - Executing <Task(PythonOperator): fetch_geolocation_data> on 2025-08-17 00:00:00+00:00
[2025-08-18T01:24:31.671+0000] {standard_task_runner.py:90} INFO - Running: ['***', 'tasks', 'run', 'weather_data_pipeline', 'fetch_geolocation_data', 'scheduled__2025-08-17T00:00:00+00:00', '--job-id', '58', '--raw', '--subdir', 'DAGS_FOLDER/weather_dags.py', '--cfg-path', '/tmp/tmpxdwf0bwp']
[2025-08-18T01:24:31.673+0000] {standard_task_runner.py:91} INFO - Job 58: Subtask fetch_geolocation_data
[2025-08-18T01:24:31.673+0000] {logging_mixin.py:188} WARNING - /home/***/.local/lib/python3.12/site-packages/***/task/task_runner/standard_task_runner.py:61 DeprecationWarning: This process (pid=391) is multi-threaded, use of fork() may lead to deadlocks in the child.
[2025-08-18T01:24:31.674+0000] {standard_task_runner.py:63} INFO - Started process 393 to run task
[2025-08-18T01:24:31.727+0000] {task_command.py:426} INFO - Running <TaskInstance: weather_data_pipeline.fetch_geolocation_data scheduled__2025-08-17T00:00:00+00:00 [running]> on host 23863237c1a1
[2025-08-18T01:24:31.818+0000] {taskinstance.py:2648} INFO - Exporting env vars: AIRFLOW_CTX_DAG_OWNER='Hendi Irwanto' AIRFLOW_CTX_DAG_ID='weather_data_pipeline' AIRFLOW_CTX_TASK_ID='fetch_geolocation_data' AIRFLOW_CTX_EXECUTION_DATE='2025-08-17T00:00:00+00:00' AIRFLOW_CTX_TRY_NUMBER='2' AIRFLOW_CTX_DAG_RUN_ID='scheduled__2025-08-17T00:00:00+00:00'
[2025-08-18T01:24:31.819+0000] {taskinstance.py:430} INFO - ::endgroup::
[2025-08-18T01:24:32.394+0000] {logging_mixin.py:188} INFO - Geolocation data fetched successfully.
[2025-08-18T01:24:32.400+0000] {logging_mixin.py:188} INFO - Geolocation data processed into DataFrame. Shape: (100, 5)
[2025-08-18T01:26:48.452+0000] {logging_mixin.py:188} INFO - An error occurred while loading data into the database: (psycopg2.OperationalError) connection to server at "172.18.0.2", port 5432 failed: Connection timed out
	Is the server running on that host and accepting TCP/IP connections?

(Background on this error at: https://sqlalche.me/e/14/e3q8)
[2025-08-18T01:26:48.453+0000] {python.py:237} INFO - Done. Returned value was: None
[2025-08-18T01:26:48.454+0000] {taskinstance.py:441} INFO - ::group::Post task execution logs
[2025-08-18T01:26:48.472+0000] {taskinstance.py:1206} INFO - Marking task as SUCCESS. dag_id=weather_data_pipeline, task_id=fetch_geolocation_data, run_id=scheduled__2025-08-17T00:00:00+00:00, execution_date=20250817T000000, start_date=20250818T012431, end_date=20250818T012648
[2025-08-18T01:26:48.506+0000] {local_task_job_runner.py:240} INFO - Task exited with return code 0
[2025-08-18T01:26:48.526+0000] {taskinstance.py:3503} INFO - 1 downstream tasks scheduled from follow-on schedule check
[2025-08-18T01:26:48.527+0000] {local_task_job_runner.py:222} INFO - ::endgroup::
