[2025-08-10T15:35:48.799+0000] {local_task_job_runner.py:120} INFO - ::group::Pre task execution logs
[2025-08-10T15:35:48.928+0000] {taskinstance.py:2076} INFO - Dependencies all met for dep_context=non-requeueable deps ti=<TaskInstance: weather_data_pipeline.run_dbt_transformations scheduled__2025-08-09T00:00:00+00:00 [queued]>
[2025-08-10T15:35:48.933+0000] {taskinstance.py:2076} INFO - Dependencies all met for dep_context=requeueable deps ti=<TaskInstance: weather_data_pipeline.run_dbt_transformations scheduled__2025-08-09T00:00:00+00:00 [queued]>
[2025-08-10T15:35:48.933+0000] {taskinstance.py:2306} INFO - Starting attempt 2 of 2
[2025-08-10T15:35:48.941+0000] {taskinstance.py:2330} INFO - Executing <Task(PythonOperator): run_dbt_transformations> on 2025-08-09 00:00:00+00:00
[2025-08-10T15:35:48.948+0000] {standard_task_runner.py:90} INFO - Running: ['***', 'tasks', 'run', 'weather_data_pipeline', 'run_dbt_transformations', 'scheduled__2025-08-09T00:00:00+00:00', '--job-id', '10', '--raw', '--subdir', 'DAGS_FOLDER/weather_dags.py', '--cfg-path', '/tmp/tmpwcuj0avl']
[2025-08-10T15:35:48.950+0000] {standard_task_runner.py:91} INFO - Job 10: Subtask run_dbt_transformations
[2025-08-10T15:35:48.950+0000] {logging_mixin.py:188} WARNING - /home/***/.local/lib/python3.12/site-packages/***/task/task_runner/standard_task_runner.py:61 DeprecationWarning: This process (pid=988) is multi-threaded, use of fork() may lead to deadlocks in the child.
[2025-08-10T15:35:48.951+0000] {standard_task_runner.py:63} INFO - Started process 990 to run task
[2025-08-10T15:35:48.996+0000] {task_command.py:426} INFO - Running <TaskInstance: weather_data_pipeline.run_dbt_transformations scheduled__2025-08-09T00:00:00+00:00 [running]> on host a958f78a1f45
[2025-08-10T15:35:49.068+0000] {taskinstance.py:2648} INFO - Exporting env vars: AIRFLOW_CTX_DAG_OWNER='Hendi Irwanto' AIRFLOW_CTX_DAG_ID='weather_data_pipeline' AIRFLOW_CTX_TASK_ID='run_dbt_transformations' AIRFLOW_CTX_EXECUTION_DATE='2025-08-09T00:00:00+00:00' AIRFLOW_CTX_TRY_NUMBER='2' AIRFLOW_CTX_DAG_RUN_ID='scheduled__2025-08-09T00:00:00+00:00'
[2025-08-10T15:35:49.068+0000] {taskinstance.py:430} INFO - ::endgroup::
[2025-08-10T15:35:49.079+0000] {taskinstance.py:441} INFO - ::group::Post task execution logs
[2025-08-10T15:35:49.079+0000] {taskinstance.py:2905} ERROR - Task failed with exception
Traceback (most recent call last):
  File "/home/airflow/.local/lib/python3.12/site-packages/airflow/models/taskinstance.py", line 465, in _execute_task
    result = _execute_callable(context=context, **execute_callable_kwargs)
             ^^^^^^^^^^^^^^^^^^^^^^^^^^^^^^^^^^^^^^^^^^^^^^^^^^^^^^^^^^^^^
  File "/home/airflow/.local/lib/python3.12/site-packages/airflow/models/taskinstance.py", line 432, in _execute_callable
    return execute_callable(context=context, **execute_callable_kwargs)
           ^^^^^^^^^^^^^^^^^^^^^^^^^^^^^^^^^^^^^^^^^^^^^^^^^^^^^^^^^^^^
  File "/home/airflow/.local/lib/python3.12/site-packages/airflow/models/baseoperator.py", line 401, in wrapper
    return func(self, *args, **kwargs)
           ^^^^^^^^^^^^^^^^^^^^^^^^^^^
  File "/home/airflow/.local/lib/python3.12/site-packages/airflow/operators/python.py", line 235, in execute
    return_value = self.execute_callable()
                   ^^^^^^^^^^^^^^^^^^^^^^^
  File "/home/airflow/.local/lib/python3.12/site-packages/airflow/operators/python.py", line 252, in execute_callable
    return self.python_callable(*self.op_args, **self.op_kwargs)
           ^^^^^^^^^^^^^^^^^^^^^^^^^^^^^^^^^^^^^^^^^^^^^^^^^^^^^
  File "/opt/airflow/dags/weather_dags.py", line 20, in run_dbt_transformations
    subprocess.run(["dbt", "run", "--profiles-dir", "/opt/data-engineer/weather-project/dbt/weather_dbt"], check=True)
  File "/usr/local/lib/python3.12/subprocess.py", line 548, in run
    with Popen(*popenargs, **kwargs) as process:
         ^^^^^^^^^^^^^^^^^^^^^^^^^^^
  File "/usr/local/lib/python3.12/subprocess.py", line 1026, in __init__
    self._execute_child(args, executable, preexec_fn, close_fds,
  File "/usr/local/lib/python3.12/subprocess.py", line 1955, in _execute_child
    raise child_exception_type(errno_num, err_msg, err_filename)
FileNotFoundError: [Errno 2] No such file or directory: 'dbt'
[2025-08-10T15:35:49.090+0000] {taskinstance.py:1206} INFO - Marking task as FAILED. dag_id=weather_data_pipeline, task_id=run_dbt_transformations, run_id=scheduled__2025-08-09T00:00:00+00:00, execution_date=20250809T000000, start_date=20250810T153548, end_date=20250810T153549
[2025-08-10T15:35:49.097+0000] {standard_task_runner.py:110} ERROR - Failed to execute job 10 for task run_dbt_transformations ([Errno 2] No such file or directory: 'dbt'; 990)
[2025-08-10T15:35:49.136+0000] {local_task_job_runner.py:240} INFO - Task exited with return code 1
[2025-08-10T15:35:49.153+0000] {taskinstance.py:3503} INFO - 0 downstream tasks scheduled from follow-on schedule check
[2025-08-10T15:35:49.156+0000] {local_task_job_runner.py:222} INFO - ::endgroup::
[2025-08-10T16:44:28.376+0000] {local_task_job_runner.py:120} INFO - ::group::Pre task execution logs
[2025-08-10T16:44:28.502+0000] {taskinstance.py:2076} INFO - Dependencies all met for dep_context=non-requeueable deps ti=<TaskInstance: weather_data_pipeline.run_dbt_transformations scheduled__2025-08-09T00:00:00+00:00 [queued]>
[2025-08-10T16:44:28.507+0000] {taskinstance.py:2076} INFO - Dependencies all met for dep_context=requeueable deps ti=<TaskInstance: weather_data_pipeline.run_dbt_transformations scheduled__2025-08-09T00:00:00+00:00 [queued]>
[2025-08-10T16:44:28.507+0000] {taskinstance.py:2306} INFO - Starting attempt 2 of 3
[2025-08-10T16:44:28.515+0000] {taskinstance.py:2330} INFO - Executing <Task(BashOperator): run_dbt_transformations> on 2025-08-09 00:00:00+00:00
[2025-08-10T16:44:28.522+0000] {standard_task_runner.py:90} INFO - Running: ['***', 'tasks', 'run', 'weather_data_pipeline', 'run_dbt_transformations', 'scheduled__2025-08-09T00:00:00+00:00', '--job-id', '27', '--raw', '--subdir', 'DAGS_FOLDER/weather_dags.py', '--cfg-path', '/tmp/tmpjc0_1omr']
[2025-08-10T16:44:28.524+0000] {standard_task_runner.py:91} INFO - Job 27: Subtask run_dbt_transformations
[2025-08-10T16:44:28.524+0000] {logging_mixin.py:188} WARNING - /home/***/.local/lib/python3.12/site-packages/***/task/task_runner/standard_task_runner.py:61 DeprecationWarning: This process (pid=386) is multi-threaded, use of fork() may lead to deadlocks in the child.
[2025-08-10T16:44:28.525+0000] {standard_task_runner.py:63} INFO - Started process 388 to run task
[2025-08-10T16:44:28.569+0000] {task_command.py:426} INFO - Running <TaskInstance: weather_data_pipeline.run_dbt_transformations scheduled__2025-08-09T00:00:00+00:00 [running]> on host 49775de909c4
[2025-08-10T16:44:28.642+0000] {taskinstance.py:2648} INFO - Exporting env vars: AIRFLOW_CTX_DAG_OWNER='Hendi Irwanto' AIRFLOW_CTX_DAG_ID='weather_data_pipeline' AIRFLOW_CTX_TASK_ID='run_dbt_transformations' AIRFLOW_CTX_EXECUTION_DATE='2025-08-09T00:00:00+00:00' AIRFLOW_CTX_TRY_NUMBER='2' AIRFLOW_CTX_DAG_RUN_ID='scheduled__2025-08-09T00:00:00+00:00'
[2025-08-10T16:44:28.643+0000] {taskinstance.py:430} INFO - ::endgroup::
[2025-08-10T16:44:28.652+0000] {subprocess.py:63} INFO - Tmp dir root location: /tmp
[2025-08-10T16:44:28.652+0000] {subprocess.py:75} INFO - Running command: ['/usr/bin/bash', '-c', 'dbt run --project-dir /opt/data-engineer/weather-project/dbt/weather_dbt --profiles-dir /opt/data-engineer/weather-project/dbt/weather_dbt']
[2025-08-10T16:44:28.661+0000] {subprocess.py:86} INFO - Output:
[2025-08-10T16:44:30.010+0000] {subprocess.py:93} INFO - [0m16:44:30  Running with dbt=1.10.7
[2025-08-10T16:44:30.013+0000] {subprocess.py:93} INFO - [0m16:44:30  Encountered an error:
[2025-08-10T16:44:30.013+0000] {subprocess.py:93} INFO - Runtime Error
[2025-08-10T16:44:30.013+0000] {subprocess.py:93} INFO -   Could not find profile named 'weather_dbt'
[2025-08-10T16:44:31.231+0000] {subprocess.py:97} INFO - Command exited with return code 2
[2025-08-10T16:44:31.231+0000] {taskinstance.py:441} INFO - ::group::Post task execution logs
[2025-08-10T16:44:31.242+0000] {taskinstance.py:2905} ERROR - Task failed with exception
Traceback (most recent call last):
  File "/home/airflow/.local/lib/python3.12/site-packages/airflow/models/taskinstance.py", line 465, in _execute_task
    result = _execute_callable(context=context, **execute_callable_kwargs)
             ^^^^^^^^^^^^^^^^^^^^^^^^^^^^^^^^^^^^^^^^^^^^^^^^^^^^^^^^^^^^^
  File "/home/airflow/.local/lib/python3.12/site-packages/airflow/models/taskinstance.py", line 432, in _execute_callable
    return execute_callable(context=context, **execute_callable_kwargs)
           ^^^^^^^^^^^^^^^^^^^^^^^^^^^^^^^^^^^^^^^^^^^^^^^^^^^^^^^^^^^^
  File "/home/airflow/.local/lib/python3.12/site-packages/airflow/models/baseoperator.py", line 401, in wrapper
    return func(self, *args, **kwargs)
           ^^^^^^^^^^^^^^^^^^^^^^^^^^^
  File "/home/airflow/.local/lib/python3.12/site-packages/airflow/operators/bash.py", line 243, in execute
    raise AirflowException(
airflow.exceptions.AirflowException: Bash command failed. The command returned a non-zero exit code 2.
[2025-08-10T16:44:31.245+0000] {taskinstance.py:1206} INFO - Marking task as UP_FOR_RETRY. dag_id=weather_data_pipeline, task_id=run_dbt_transformations, run_id=scheduled__2025-08-09T00:00:00+00:00, execution_date=20250809T000000, start_date=20250810T164428, end_date=20250810T164431
[2025-08-10T16:44:31.253+0000] {standard_task_runner.py:110} ERROR - Failed to execute job 27 for task run_dbt_transformations (Bash command failed. The command returned a non-zero exit code 2.; 388)
[2025-08-10T16:44:31.296+0000] {local_task_job_runner.py:240} INFO - Task exited with return code 1
[2025-08-10T16:44:31.314+0000] {taskinstance.py:3503} INFO - 0 downstream tasks scheduled from follow-on schedule check
[2025-08-10T16:44:31.315+0000] {local_task_job_runner.py:222} INFO - ::endgroup::
