[2025-08-10T15:44:00.094+0000] {local_task_job_runner.py:120} INFO - ::group::Pre task execution logs
[2025-08-10T15:44:00.225+0000] {taskinstance.py:2076} INFO - Dependencies all met for dep_context=non-requeueable deps ti=<TaskInstance: weather_data_pipeline.run_dbt_transformations manual__2025-08-10T15:42:40.586252+00:00 [queued]>
[2025-08-10T15:44:00.231+0000] {taskinstance.py:2076} INFO - Dependencies all met for dep_context=requeueable deps ti=<TaskInstance: weather_data_pipeline.run_dbt_transformations manual__2025-08-10T15:42:40.586252+00:00 [queued]>
[2025-08-10T15:44:00.231+0000] {taskinstance.py:2306} INFO - Starting attempt 1 of 2
[2025-08-10T15:44:00.238+0000] {taskinstance.py:2330} INFO - Executing <Task(BashOperator): run_dbt_transformations> on 2025-08-10 15:42:40.586252+00:00
[2025-08-10T15:44:00.245+0000] {standard_task_runner.py:90} INFO - Running: ['***', 'tasks', 'run', 'weather_data_pipeline', 'run_dbt_transformations', 'manual__2025-08-10T15:42:40.586252+00:00', '--job-id', '13', '--raw', '--subdir', 'DAGS_FOLDER/weather_dags.py', '--cfg-path', '/tmp/tmpa2mgnkbx']
[2025-08-10T15:44:00.247+0000] {standard_task_runner.py:91} INFO - Job 13: Subtask run_dbt_transformations
[2025-08-10T15:44:00.248+0000] {logging_mixin.py:188} WARNING - /home/***/.local/lib/python3.12/site-packages/***/task/task_runner/standard_task_runner.py:61 DeprecationWarning: This process (pid=1196) is multi-threaded, use of fork() may lead to deadlocks in the child.
[2025-08-10T15:44:00.248+0000] {standard_task_runner.py:63} INFO - Started process 1198 to run task
[2025-08-10T15:44:00.292+0000] {task_command.py:426} INFO - Running <TaskInstance: weather_data_pipeline.run_dbt_transformations manual__2025-08-10T15:42:40.586252+00:00 [running]> on host a958f78a1f45
[2025-08-10T15:44:00.364+0000] {taskinstance.py:2648} INFO - Exporting env vars: AIRFLOW_CTX_DAG_OWNER='Hendi Irwanto' AIRFLOW_CTX_DAG_ID='weather_data_pipeline' AIRFLOW_CTX_TASK_ID='run_dbt_transformations' AIRFLOW_CTX_EXECUTION_DATE='2025-08-10T15:42:40.586252+00:00' AIRFLOW_CTX_TRY_NUMBER='1' AIRFLOW_CTX_DAG_RUN_ID='manual__2025-08-10T15:42:40.586252+00:00'
[2025-08-10T15:44:00.365+0000] {taskinstance.py:430} INFO - ::endgroup::
[2025-08-10T15:44:00.374+0000] {subprocess.py:63} INFO - Tmp dir root location: /tmp
[2025-08-10T15:44:00.375+0000] {subprocess.py:75} INFO - Running command: ['/usr/bin/bash', '-c', 'dbt run --profiles-dir /opt/data-engineer/weather-project/dbt/weather_dbt']
[2025-08-10T15:44:00.384+0000] {subprocess.py:86} INFO - Output:
[2025-08-10T15:44:00.386+0000] {subprocess.py:93} INFO - /usr/bin/bash: line 1: dbt: command not found
[2025-08-10T15:44:00.386+0000] {subprocess.py:97} INFO - Command exited with return code 127
[2025-08-10T15:44:00.386+0000] {taskinstance.py:441} INFO - ::group::Post task execution logs
[2025-08-10T15:44:00.397+0000] {taskinstance.py:2905} ERROR - Task failed with exception
Traceback (most recent call last):
  File "/home/airflow/.local/lib/python3.12/site-packages/airflow/models/taskinstance.py", line 465, in _execute_task
    result = _execute_callable(context=context, **execute_callable_kwargs)
             ^^^^^^^^^^^^^^^^^^^^^^^^^^^^^^^^^^^^^^^^^^^^^^^^^^^^^^^^^^^^^
  File "/home/airflow/.local/lib/python3.12/site-packages/airflow/models/taskinstance.py", line 432, in _execute_callable
    return execute_callable(context=context, **execute_callable_kwargs)
           ^^^^^^^^^^^^^^^^^^^^^^^^^^^^^^^^^^^^^^^^^^^^^^^^^^^^^^^^^^^^
  File "/home/airflow/.local/lib/python3.12/site-packages/airflow/models/baseoperator.py", line 401, in wrapper
    return func(self, *args, **kwargs)
           ^^^^^^^^^^^^^^^^^^^^^^^^^^^
  File "/home/airflow/.local/lib/python3.12/site-packages/airflow/operators/bash.py", line 243, in execute
    raise AirflowException(
airflow.exceptions.AirflowException: Bash command failed. The command returned a non-zero exit code 127.
[2025-08-10T15:44:00.400+0000] {taskinstance.py:1206} INFO - Marking task as UP_FOR_RETRY. dag_id=weather_data_pipeline, task_id=run_dbt_transformations, run_id=manual__2025-08-10T15:42:40.586252+00:00, execution_date=20250810T154240, start_date=20250810T154400, end_date=20250810T154400
[2025-08-10T15:44:00.407+0000] {standard_task_runner.py:110} ERROR - Failed to execute job 13 for task run_dbt_transformations (Bash command failed. The command returned a non-zero exit code 127.; 1198)
[2025-08-10T15:44:00.424+0000] {local_task_job_runner.py:240} INFO - Task exited with return code 1
[2025-08-10T15:44:00.442+0000] {taskinstance.py:3503} INFO - 0 downstream tasks scheduled from follow-on schedule check
[2025-08-10T15:44:00.443+0000] {local_task_job_runner.py:222} INFO - ::endgroup::
